src/assets/sample.json
[{
    "Time": "09:00:31.529389",
    "Bid1": 4.768,
    "Bid1Size": 1175,
    "Ask1": 4.77,
    "Ask1Size": 3611,
    "Bid2": 4.7675,
    "Bid2Size": 3729,
    "Ask2": 4.7705,
    "Ask2Size": 49614,
    "Bid3": 4.767,
    "Bid3Size": 8965,
    "Ask3": 4.771,
    "Ask3Size": 3674,
    "Bid4": 4.7665,
    "Bid4Size": 9208,
    "Ask4": 4.7715,
    "Ask4Size": 4172,
    "Bid5": 4.766,
    "Bid5Size": 9041,
    "Ask5": 4.772,
    "Ask5Size": 6097,
    "Bid6": 4.7655,
    "Bid6Size": 2228,
    "Ask6": 4.7725,
    "Ask6Size": 3740,
    "Bid7": 4.765,
    "Bid7Size": 9328,
    "Ask7": 4.773,
    "Ask7Size": 5017,
    "Bid8": 4.7645,
    "Bid8Size": 8074,
    "Ask8": 4.7735,
    "Ask8Size": 8851,
    "Bid9": 4.764,
    "Bid9Size": 5006,
    "Ask9": 4.774,
    "Ask9Size": 9483,
    "Bid10": 4.7635,
    "Bid10Size": 3583,
    "Ask10": 4.7745,
    "Ask10Size": 5082
},
{
    "Time": "09:00:49.066691",
    "Bid1": 4.7515,
    "Bid1Size": 1133,
    "Ask1": 4.756,
    "Ask1Size": 1086,
    "Bid2": 4.751,
    "Bid2Size": 3714,
    "Ask2": 4.7565,
    "Ask2Size": 2230,
    "Bid3": 4.7505,
    "Bid3Size": 6673,
    "Ask3": 4.757,
    "Ask3Size": 6546,
    "Bid4": 4.75,
    "Bid4Size": 11541,
    "Ask4": 4.7575,
    "Ask4Size": 3962,
    "Bid5": 4.7495,
    "Bid5Size": 5243,
    "Ask5": 4.758,
    "Ask5Size": 3518,
    "Bid6": 4.749,
    "Bid6Size": 5020,
    "Ask6": 4.7585,
    "Ask6Size": 3510,
    "Bid7": 4.7485,
    "Bid7Size": 3545,
    "Ask7": 4.759,
    "Ask7Size": 3908,
    "Bid8": 4.748,
    "Bid8Size": 9198,
    "Ask8": 4.7595,
    "Ask8Size": 3568,
    "Bid9": 4.7475,
    "Bid9Size": 8210,
    "Ask9": 4.76,
    "Ask9Size": 33636,
    "Bid10": 4.747,
    "Bid10Size": 9454,
    "Ask10": 4.7605,
    "Ask10Size": 1426
},
{
    "Time": "09:01:01.146265",
    "Bid1": 4.7485,
    "Bid1Size": 1314,
    "Ask1": 4.75,
    "Ask1Size": 2552,
    "Bid2": 4.748,
    "Bid2Size": 1819,
    "Ask2": 4.7505,
    "Ask2Size": 5800,
    "Bid3": 4.7475,
    "Bid3Size": 319,
    "Ask3": 4.751,
    "Ask3Size": 7735,
    "Bid4": 4.747,
    "Bid4Size": 5235,
    "Ask4": 4.7515,
    "Ask4Size": 9184,
    "Bid5": 4.7465,
    "Bid5Size": 4829,
    "Ask5": 4.752,
    "Ask5Size": 8308,
    "Bid6": 4.746,
    "Bid6Size": 9029,
    "Ask6": 4.7525,
    "Ask6Size": 10827,
    "Bid7": 4.7455,
    "Bid7Size": 9860,
    "Ask7": 4.753,
    "Ask7Size": 10819,
    "Bid8": 4.745,
    "Bid8Size": 10560,
    "Ask8": 4.7535,
    "Ask8Size": 10998,
    "Bid9": 4.7445,
    "Bid9Size": 8861,
    "Ask9": 4.754,
    "Ask9Size": 5044,
    "Bid10": 4.744,
    "Bid10Size": 10604,
    "Ask10": 4.7545,
    "Ask10Size": 5071
},
{
    "Time": "09:01:10.972224",
    "Bid1": 4.751,
    "Bid1Size": 3687,
    "Ask1": 4.754,
    "Ask1Size": 234,
    "Bid2": 4.7505,
    "Bid2Size": 11640,
    "Ask2": 4.7545,
    "Ask2Size": 1598,
    "Bid3": 4.75,
    "Bid3Size": 9788,
    "Ask3": 4.755,
    "Ask3Size": 8396,
    "Bid4": 4.7495,
    "Bid4Size": 11304,
    "Ask4": 4.7555,
    "Ask4Size": 10213,
    "Bid5": 4.749,
    "Bid5Size": 9428,
    "Ask5": 4.756,
    "Ask5Size": 8683,
    "Bid6": 4.7485,
    "Bid6Size": 8900,
    "Ask6": 4.7565,
    "Ask6Size": 8733,
    "Bid7": 4.748,
    "Bid7Size": 9443,
    "Ask7": 4.757,
    "Ask7Size": 18568,
    "Bid8": 4.7475,
    "Bid8Size": 3457,
    "Ask8": 4.7575,
    "Ask8Size": 8822,
    "Bid9": 4.747,
    "Bid9Size": 6761,
    "Ask9": 4.758,
    "Ask9Size": 8363,
    "Bid10": 4.7465,
    "Bid10Size": 6589,
    "Ask10": 4.7585,
    "Ask10Size": 3512
},
{
    "Time": "09:01:21.046609",
    "Bid1": 4.749,
    "Bid1Size": 222,
    "Ask1": 4.7505,
    "Ask1Size": 2304,
    "Bid2": 4.7485,
    "Bid2Size": 1922,
    "Ask2": 4.751,
    "Ask2Size": 7016,
    "Bid3": 4.748,
    "Bid3Size": 2022,
    "Ask3": 4.7515,
    "Ask3Size": 9321,
    "Bid4": 4.7475,
    "Bid4Size": 772,
    "Ask4": 4.752,
    "Ask4Size": 9558,
    "Bid5": 4.747,
    "Bid5Size": 2552,
    "Ask5": 4.7525,
    "Ask5Size": 11570,
    "Bid6": 4.7465,
    "Bid6Size": 2107,
    "Ask6": 4.753,
    "Ask6Size": 11364,
    "Bid7": 4.746,
    "Bid7Size": 2554,
    "Ask7": 4.7535,
    "Ask7Size": 4964,
    "Bid8": 4.7455,
    "Bid8Size": 2436,
    "Ask8": 4.754,
    "Ask8Size": 3538,
    "Bid9": 4.745,
    "Bid9Size": 5304,
    "Ask9": 4.7545,
    "Ask9Size": 3502,
    "Bid10": 4.7445,
    "Bid10Size": 5295,
    "Ask10": 4.755,
    "Ask10Size": 11056
},
{
    "Time": "09:01:32.353774",
    "Bid1": 4.7485,
    "Bid1Size": 3457,
    "Ask1": 4.751,
    "Ask1Size": 4966,
    "Bid2": 4.748,
    "Bid2Size": 1655,
    "Ask2": 4.7515,
    "Ask2Size": 5707,
    "Bid3": 4.7475,
    "Bid3Size": 8583,
    "Ask3": 4.752,
    "Ask3Size": 3669,
    "Bid4": 4.747,
    "Bid4Size": 3941,
    "Ask4": 4.7525,
    "Ask4Size": 15848,
    "Bid5": 4.7465,
    "Bid5Size": 5624,
    "Ask5": 4.753,
    "Ask5Size": 8453,
    "Bid6": 4.746,
    "Bid6Size": 5421,
    "Ask6": 4.7535,
    "Ask6Size": 12767,
    "Bid7": 4.7455,
    "Bid7Size": 7006,
    "Ask7": 4.754,
    "Ask7Size": 5301,
    "Bid8": 4.745,
    "Bid8Size": 7129,
    "Ask8": 4.7545,
    "Ask8Size": 9502,
    "Bid9": 4.7445,
    "Bid9Size": 13718,
    "Ask9": 4.755,
    "Ask9Size": 9837,
    "Bid10": 4.744,
    "Bid10Size": 7429,
    "Ask10": 4.7555,
    "Ask10Size": 3440
},
{
    "Time": "09:01:43.746262",
    "Bid1": 4.749,
    "Bid1Size": 1426,
    "Ask1": 4.751,
    "Ask1Size": 2366,
    "Bid2": 4.7485,
    "Bid2Size": 6722,
    "Ask2": 4.7515,
    "Ask2Size": 5735,
    "Bid3": 4.748,
    "Bid3Size": 7278,
    "Ask3": 4.752,
    "Ask3Size": 12060,
    "Bid4": 4.7475,
    "Bid4Size": 12966,
    "Ask4": 4.7525,
    "Ask4Size": 11347,
    "Bid5": 4.747,
    "Bid5Size": 11479,
    "Ask5": 4.753,
    "Ask5Size": 12378,
    "Bid6": 4.7465,
    "Bid6Size": 14818,
    "Ask6": 4.7535,
    "Ask6Size": 14052,
    "Bid7": 4.746,
    "Bid7Size": 8960,
    "Ask7": 4.754,
    "Ask7Size": 13266,
    "Bid8": 4.7455,
    "Bid8Size": 16545,
    "Ask8": 4.7545,
    "Ask8Size": 12532,
    "Bid9": 4.745,
    "Bid9Size": 11917,
    "Ask9": 4.755,
    "Ask9Size": 21168,
    "Bid10": 4.7445,
    "Bid10Size": 12108,
    "Ask10": 4.7555,
    "Ask10Size": 10616
},
{
    "Time": "09:01:53.07568",
    "Bid1": 4.753,
    "Bid1Size": 1291,
    "Ask1": 4.7555,
    "Ask1Size": 6952,
    "Bid2": 4.7525,
    "Bid2Size": 9605,
    "Ask2": 4.756,
    "Ask2Size": 12283,
    "Bid3": 4.752,
    "Bid3Size": 5807,
    "Ask3": 4.7565,
    "Ask3Size": 13467,
    "Bid4": 4.7515,
    "Bid4Size": 9002,
    "Ask4": 4.757,
    "Ask4Size": 7394,
    "Bid5": 4.751,
    "Bid5Size": 6242,
    "Ask5": 4.7575,
    "Ask5Size": 11089,
    "Bid6": 4.7505,
    "Bid6Size": 13236,
    "Ask6": 4.758,
    "Ask6Size": 10511,
    "Bid7": 4.75,
    "Bid7Size": 5630,
    "Ask7": 4.7585,
    "Ask7Size": 11589,
    "Bid8": 4.7495,
    "Bid8Size": 7005,
    "Ask8": 4.759,
    "Ask8Size": 42369,
    "Bid9": 4.749,
    "Bid9Size": 7159,
    "Ask9": 4.7595,
    "Ask9Size": 11219,
    "Bid10": 4.7485,
    "Bid10Size": 11358,
    "Ask10": 4.76,
    "Ask10Size": 11508
},
{
    "Time": "09:02:03.9267",
    "Bid1": 4.749,
    "Bid1Size": 2035,
    "Ask1": 4.75,
    "Ask1Size": 751,
    "Bid2": 4.7485,
    "Bid2Size": 8845,
    "Ask2": 4.7505,
    "Ask2Size": 53038,
    "Bid3": 4.748,
    "Bid3Size": 7393,
    "Ask3": 4.751,
    "Ask3Size": 2489,
    "Bid4": 4.7475,
    "Bid4Size": 16187,
    "Ask4": 4.7515,
    "Ask4Size": 4103,
    "Bid5": 4.747,
    "Bid5Size": 11222,
    "Ask5": 4.752,
    "Ask5Size": 106921,
    "Bid6": 4.7465,
    "Bid6Size": 14364,
    "Ask6": 4.7525,
    "Ask6Size": 5808,
    "Bid7": 4.746,
    "Bid7Size": 11500,
    "Ask7": 4.753,
    "Ask7Size": 6999,
    "Bid8": 4.7455,
    "Bid8Size": 14256,
    "Ask8": 4.7535,
    "Ask8Size": 7201,
    "Bid9": 4.745,
    "Bid9Size": 8490,
    "Ask9": 4.754,
    "Ask9Size": 11589,
    "Bid10": 4.7445,
    "Bid10Size": 10521,
    "Ask10": 4.7545,
    "Ask10Size": 11708
},
{
    "Time": "09:02:11.470023",
    "Bid1": 4.735,
    "Bid1Size": 604,
    "Ask1": 4.737,
    "Ask1Size": 4267,
    "Bid2": 4.7345,
    "Bid2Size": 2304,
